[2024-07-25T00:07:41.518+0000] {taskinstance.py:1083} INFO - Dependencies all met for <TaskInstance: examplo_dag_run_dag.tsk2 manual__2024-07-25T00:07:35.258217+00:00 [queued]>
[2024-07-25T00:07:41.523+0000] {taskinstance.py:1083} INFO - Dependencies all met for <TaskInstance: examplo_dag_run_dag.tsk2 manual__2024-07-25T00:07:35.258217+00:00 [queued]>
[2024-07-25T00:07:41.524+0000] {taskinstance.py:1279} INFO - 
--------------------------------------------------------------------------------
[2024-07-25T00:07:41.524+0000] {taskinstance.py:1280} INFO - Starting attempt 1 of 1
[2024-07-25T00:07:41.524+0000] {taskinstance.py:1281} INFO - 
--------------------------------------------------------------------------------
[2024-07-25T00:07:41.530+0000] {taskinstance.py:1300} INFO - Executing <Task(TriggerDagRunOperator): tsk2> on 2024-07-25 00:07:35.258217+00:00
[2024-07-25T00:07:41.533+0000] {standard_task_runner.py:55} INFO - Started process 26971 to run task
[2024-07-25T00:07:41.535+0000] {standard_task_runner.py:82} INFO - Running: ['***', 'tasks', 'run', 'examplo_dag_run_dag', 'tsk2', 'manual__2024-07-25T00:07:35.258217+00:00', '--job-id', '1323', '--raw', '--subdir', 'DAGS_FOLDER/examplo_dag_run_dag.py', '--cfg-path', '/tmp/tmpfcb6hw7x']
[2024-07-25T00:07:41.535+0000] {standard_task_runner.py:83} INFO - Job 1323: Subtask tsk2
[2024-07-25T00:07:41.565+0000] {task_command.py:388} INFO - Running <TaskInstance: examplo_dag_run_dag.tsk2 manual__2024-07-25T00:07:35.258217+00:00 [running]> on host 448a9c84d52e
[2024-07-25T00:07:41.598+0000] {taskinstance.py:1509} INFO - Exporting the following env vars:
AIRFLOW_CTX_DAG_OWNER=***
AIRFLOW_CTX_DAG_ID=examplo_dag_run_dag
AIRFLOW_CTX_TASK_ID=tsk2
AIRFLOW_CTX_EXECUTION_DATE=2024-07-25T00:07:35.258217+00:00
AIRFLOW_CTX_TRY_NUMBER=1
AIRFLOW_CTX_DAG_RUN_ID=manual__2024-07-25T00:07:35.258217+00:00
[2024-07-25T00:07:41.608+0000] {taskinstance.py:1768} ERROR - Task failed with exception
Traceback (most recent call last):
  File "/home/airflow/.local/lib/python3.7/site-packages/airflow/operators/trigger_dagrun.py", line 144, in execute
    replace_microseconds=False,
  File "/home/airflow/.local/lib/python3.7/site-packages/airflow/api/common/trigger_dag.py", line 119, in trigger_dag
    raise DagNotFound(f"Dag id {dag_id} not found in DagModel")
airflow.exceptions.DagNotFound: Dag id exemplo_dag_run_operator not found in DagModel
[2024-07-25T00:07:41.610+0000] {taskinstance.py:1323} INFO - Marking task as FAILED. dag_id=examplo_dag_run_dag, task_id=tsk2, execution_date=20240725T000735, start_date=20240725T000741, end_date=20240725T000741
[2024-07-25T00:07:41.615+0000] {standard_task_runner.py:105} ERROR - Failed to execute job 1323 for task tsk2 (Dag id exemplo_dag_run_operator not found in DagModel; 26971)
[2024-07-25T00:07:41.635+0000] {local_task_job.py:208} INFO - Task exited with return code 1
[2024-07-25T00:07:41.647+0000] {taskinstance.py:2578} INFO - 0 downstream tasks scheduled from follow-on schedule check
