[2024-07-25T00:05:25.271+0000] {taskinstance.py:1083} INFO - Dependencies all met for <TaskInstance: examplo_dag_run_dag.tsk2 manual__2024-07-25T00:05:18.230529+00:00 [queued]>
[2024-07-25T00:05:25.277+0000] {taskinstance.py:1083} INFO - Dependencies all met for <TaskInstance: examplo_dag_run_dag.tsk2 manual__2024-07-25T00:05:18.230529+00:00 [queued]>
[2024-07-25T00:05:25.277+0000] {taskinstance.py:1279} INFO - 
--------------------------------------------------------------------------------
[2024-07-25T00:05:25.278+0000] {taskinstance.py:1280} INFO - Starting attempt 1 of 1
[2024-07-25T00:05:25.278+0000] {taskinstance.py:1281} INFO - 
--------------------------------------------------------------------------------
[2024-07-25T00:05:25.285+0000] {taskinstance.py:1300} INFO - Executing <Task(TriggerDagRunOperator): tsk2> on 2024-07-25 00:05:18.230529+00:00
[2024-07-25T00:05:25.288+0000] {standard_task_runner.py:55} INFO - Started process 26780 to run task
[2024-07-25T00:05:25.290+0000] {standard_task_runner.py:82} INFO - Running: ['***', 'tasks', 'run', 'examplo_dag_run_dag', 'tsk2', 'manual__2024-07-25T00:05:18.230529+00:00', '--job-id', '1319', '--raw', '--subdir', 'DAGS_FOLDER/examplo_dag_run_dag.py', '--cfg-path', '/tmp/tmpl7nwipmo']
[2024-07-25T00:05:25.291+0000] {standard_task_runner.py:83} INFO - Job 1319: Subtask tsk2
[2024-07-25T00:05:25.327+0000] {task_command.py:388} INFO - Running <TaskInstance: examplo_dag_run_dag.tsk2 manual__2024-07-25T00:05:18.230529+00:00 [running]> on host 448a9c84d52e
[2024-07-25T00:05:25.368+0000] {taskinstance.py:1509} INFO - Exporting the following env vars:
AIRFLOW_CTX_DAG_OWNER=***
AIRFLOW_CTX_DAG_ID=examplo_dag_run_dag
AIRFLOW_CTX_TASK_ID=tsk2
AIRFLOW_CTX_EXECUTION_DATE=2024-07-25T00:05:18.230529+00:00
AIRFLOW_CTX_TRY_NUMBER=1
AIRFLOW_CTX_DAG_RUN_ID=manual__2024-07-25T00:05:18.230529+00:00
[2024-07-25T00:05:25.382+0000] {taskinstance.py:1768} ERROR - Task failed with exception
Traceback (most recent call last):
  File "/home/airflow/.local/lib/python3.7/site-packages/airflow/operators/trigger_dagrun.py", line 144, in execute
    replace_microseconds=False,
  File "/home/airflow/.local/lib/python3.7/site-packages/airflow/api/common/trigger_dag.py", line 119, in trigger_dag
    raise DagNotFound(f"Dag id {dag_id} not found in DagModel")
airflow.exceptions.DagNotFound: Dag id dagrundag2 not found in DagModel
[2024-07-25T00:05:25.385+0000] {taskinstance.py:1323} INFO - Marking task as FAILED. dag_id=examplo_dag_run_dag, task_id=tsk2, execution_date=20240725T000518, start_date=20240725T000525, end_date=20240725T000525
[2024-07-25T00:05:25.391+0000] {standard_task_runner.py:105} ERROR - Failed to execute job 1319 for task tsk2 (Dag id dagrundag2 not found in DagModel; 26780)
[2024-07-25T00:05:25.430+0000] {local_task_job.py:208} INFO - Task exited with return code 1
[2024-07-25T00:05:25.442+0000] {taskinstance.py:2578} INFO - 0 downstream tasks scheduled from follow-on schedule check
